<?xml version="1.0" ?>
<!-- =================================================================================== -->
<!-- |    This document was autogenerated by xacro from urdf/URDF.xacro                | -->
<!-- |    EDITING THIS FILE BY HAND IS NOT RECOMMENDED                                 | -->
<!-- =================================================================================== -->
<robot xmlns:xacro="http://www.ros.org/wiki/xacro" name="URDF">
  <material name="silver">
    <color rgba="0.700 0.700 0.700 1.000"/>
  </material>
  <transmission name="Revolute 46_tran">
    <type>transmission_interface/SimpleTransmission</type>
    <joint name="Revolute 46">
      <hardwareInterface>hardware_interface/EffortJointInterface</hardwareInterface>
    </joint>
    <actuator name="Revolute 46_actr">
      <hardwareInterface>hardware_interface/EffortJointInterface</hardwareInterface>
      <mechanicalReduction>1</mechanicalReduction>
    </actuator>
  </transmission>
  <transmission name="Revolute 54_tran">
    <type>transmission_interface/SimpleTransmission</type>
    <joint name="Revolute 54">
      <hardwareInterface>hardware_interface/EffortJointInterface</hardwareInterface>
    </joint>
    <actuator name="Revolute 54_actr">
      <hardwareInterface>hardware_interface/EffortJointInterface</hardwareInterface>
      <mechanicalReduction>1</mechanicalReduction>
    </actuator>
  </transmission>
  <transmission name="Revolute 66_tran">
    <type>transmission_interface/SimpleTransmission</type>
    <joint name="Revolute 66">
      <hardwareInterface>hardware_interface/EffortJointInterface</hardwareInterface>
    </joint>
    <actuator name="Revolute 66_actr">
      <hardwareInterface>hardware_interface/EffortJointInterface</hardwareInterface>
      <mechanicalReduction>1</mechanicalReduction>
    </actuator>
  </transmission>
  <transmission name="Revolute 67_tran">
    <type>transmission_interface/SimpleTransmission</type>
    <joint name="Revolute 67">
      <hardwareInterface>hardware_interface/EffortJointInterface</hardwareInterface>
    </joint>
    <actuator name="Revolute 67_actr">
      <hardwareInterface>hardware_interface/EffortJointInterface</hardwareInterface>
      <mechanicalReduction>1</mechanicalReduction>
    </actuator>
  </transmission>
  <transmission name="Revolute 68_tran">
    <type>transmission_interface/SimpleTransmission</type>
    <joint name="Revolute 68">
      <hardwareInterface>hardware_interface/EffortJointInterface</hardwareInterface>
    </joint>
    <actuator name="Revolute 68_actr">
      <hardwareInterface>hardware_interface/EffortJointInterface</hardwareInterface>
      <mechanicalReduction>1</mechanicalReduction>
    </actuator>
  </transmission>
  <transmission name="Revolute 69_tran">
    <type>transmission_interface/SimpleTransmission</type>
    <joint name="Revolute 69">
      <hardwareInterface>hardware_interface/EffortJointInterface</hardwareInterface>
    </joint>
    <actuator name="Revolute 69_actr">
      <hardwareInterface>hardware_interface/EffortJointInterface</hardwareInterface>
      <mechanicalReduction>1</mechanicalReduction>
    </actuator>
  </transmission>
  <transmission name="Revolute 70_tran">
    <type>transmission_interface/SimpleTransmission</type>
    <joint name="Revolute 70">
      <hardwareInterface>hardware_interface/EffortJointInterface</hardwareInterface>
    </joint>
    <actuator name="Revolute 70_actr">
      <hardwareInterface>hardware_interface/EffortJointInterface</hardwareInterface>
      <mechanicalReduction>1</mechanicalReduction>
    </actuator>
  </transmission>
  <transmission name="Revolute 71_tran">
    <type>transmission_interface/SimpleTransmission</type>
    <joint name="Revolute 71">
      <hardwareInterface>hardware_interface/EffortJointInterface</hardwareInterface>
    </joint>
    <actuator name="Revolute 71_actr">
      <hardwareInterface>hardware_interface/EffortJointInterface</hardwareInterface>
      <mechanicalReduction>1</mechanicalReduction>
    </actuator>
  </transmission>
  <transmission name="Revolute 72_tran">
    <type>transmission_interface/SimpleTransmission</type>
    <joint name="Revolute 72">
      <hardwareInterface>hardware_interface/EffortJointInterface</hardwareInterface>
    </joint>
    <actuator name="Revolute 72_actr">
      <hardwareInterface>hardware_interface/EffortJointInterface</hardwareInterface>
      <mechanicalReduction>1</mechanicalReduction>
    </actuator>
  </transmission>
  <transmission name="Revolute 73_tran">
    <type>transmission_interface/SimpleTransmission</type>
    <joint name="Revolute 73">
      <hardwareInterface>hardware_interface/EffortJointInterface</hardwareInterface>
    </joint>
    <actuator name="Revolute 73_actr">
      <hardwareInterface>hardware_interface/EffortJointInterface</hardwareInterface>
      <mechanicalReduction>1</mechanicalReduction>
    </actuator>
  </transmission>
  <transmission name="Revolute 90_tran">
    <type>transmission_interface/SimpleTransmission</type>
    <joint name="Revolute 90">
      <hardwareInterface>hardware_interface/EffortJointInterface</hardwareInterface>
    </joint>
    <actuator name="Revolute 90_actr">
      <hardwareInterface>hardware_interface/EffortJointInterface</hardwareInterface>
      <mechanicalReduction>1</mechanicalReduction>
    </actuator>
  </transmission>
  <transmission name="Revolute 91_tran">
    <type>transmission_interface/SimpleTransmission</type>
    <joint name="Revolute 91">
      <hardwareInterface>hardware_interface/EffortJointInterface</hardwareInterface>
    </joint>
    <actuator name="Revolute 91_actr">
      <hardwareInterface>hardware_interface/EffortJointInterface</hardwareInterface>
      <mechanicalReduction>1</mechanicalReduction>
    </actuator>
  </transmission>
  <transmission name="Revolute 92_tran">
    <type>transmission_interface/SimpleTransmission</type>
    <joint name="Revolute 92">
      <hardwareInterface>hardware_interface/EffortJointInterface</hardwareInterface>
    </joint>
    <actuator name="Revolute 92_actr">
      <hardwareInterface>hardware_interface/EffortJointInterface</hardwareInterface>
      <mechanicalReduction>1</mechanicalReduction>
    </actuator>
  </transmission>
  <transmission name="Revolute 93_tran">
    <type>transmission_interface/SimpleTransmission</type>
    <joint name="Revolute 93">
      <hardwareInterface>hardware_interface/EffortJointInterface</hardwareInterface>
    </joint>
    <actuator name="Revolute 93_actr">
      <hardwareInterface>hardware_interface/EffortJointInterface</hardwareInterface>
      <mechanicalReduction>1</mechanicalReduction>
    </actuator>
  </transmission>
  <gazebo>
    <plugin name="control" filename="libgazebo_ros_control.so"/>
  </gazebo>
  <gazebo reference="base_link">
    <material>Gazebo/Silver</material>
    <mu1>0.2</mu1>
    <mu2>0.2</mu2>
    <selfCollide>true</selfCollide>
    <gravity>true</gravity>
  </gazebo>
  <gazebo reference="old_component__25__1">
    <material>Gazebo/Silver</material>
    <mu1>0.2</mu1>
    <mu2>0.2</mu2>
    <selfCollide>true</selfCollide>
  </gazebo>
  <gazebo reference="old_component__23__1">
    <material>Gazebo/Silver</material>
    <mu1>0.2</mu1>
    <mu2>0.2</mu2>
    <selfCollide>true</selfCollide>
  </gazebo>
  <gazebo reference="old_component__20__1">
    <material>Gazebo/Silver</material>
    <mu1>0.2</mu1>
    <mu2>0.2</mu2>
    <selfCollide>true</selfCollide>
  </gazebo>
  <gazebo reference="old_component__19__1">
    <material>Gazebo/Silver</material>
    <mu1>0.2</mu1>
    <mu2>0.2</mu2>
    <selfCollide>true</selfCollide>
  </gazebo>
  <gazebo reference="old_component__22__1">
    <material>Gazebo/Silver</material>
    <mu1>0.2</mu1>
    <mu2>0.2</mu2>
    <selfCollide>true</selfCollide>
  </gazebo>
  <gazebo reference="old_component__21__1">
    <material>Gazebo/Silver</material>
    <mu1>0.2</mu1>
    <mu2>0.2</mu2>
    <selfCollide>true</selfCollide>
  </gazebo>
  <gazebo reference="old_component__17__1">
    <material>Gazebo/Silver</material>
    <mu1>0.2</mu1>
    <mu2>0.2</mu2>
    <selfCollide>true</selfCollide>
  </gazebo>
  <gazebo reference="old_component__16__1">
    <material>Gazebo/Silver</material>
    <mu1>0.2</mu1>
    <mu2>0.2</mu2>
    <selfCollide>true</selfCollide>
  </gazebo>
  <gazebo reference="old_component__14__1">
    <material>Gazebo/Silver</material>
    <mu1>0.2</mu1>
    <mu2>0.2</mu2>
    <selfCollide>true</selfCollide>
  </gazebo>
  <gazebo reference="old_component__18__1">
    <material>Gazebo/Silver</material>
    <mu1>0.2</mu1>
    <mu2>0.2</mu2>
    <selfCollide>true</selfCollide>
  </gazebo>
  <gazebo reference="Component104_1">
    <material>Gazebo/Silver</material>
    <mu1>0.2</mu1>
    <mu2>0.2</mu2>
    <selfCollide>true</selfCollide>
  </gazebo>
  <gazebo reference="Component103_1">
    <material>Gazebo/Silver</material>
    <mu1>0.2</mu1>
    <mu2>0.2</mu2>
    <selfCollide>true</selfCollide>
  </gazebo>
  <gazebo reference="old_component__24__1">
    <material>Gazebo/Silver</material>
    <mu1>0.2</mu1>
    <mu2>0.2</mu2>
    <selfCollide>true</selfCollide>
  </gazebo>
  <gazebo reference="old_component__15__1">
    <material>Gazebo/Silver</material>
    <mu1>0.2</mu1>
    <mu2>0.2</mu2>
    <selfCollide>true</selfCollide>
  </gazebo>
  <link name="base_link">
    <inertial>
      <origin xyz="-0.011771950657531978 0.009504064144813888 0.36652745045672347" rpy="0 0 0"/>
      <mass value="1.511497628813241"/>
      <inertia ixx="0.002624" iyy="0.000685" izz="0.00252" ixy="-0.0" iyz="-1e-05" ixz="-1e-06"/>
    </inertial>
    <visual>
      <origin xyz="0 0 0" rpy="0 0 0"/>
      <geometry>
        <mesh filename="package://URDF_description/meshes/base_link.stl" scale="0.001 0.001 0.001"/>
      </geometry>
      <material name="silver"/>
    </visual>
    <collision>
      <origin xyz="0 0 0" rpy="0 0 0"/>
      <geometry>
        <mesh filename="package://URDF_description/meshes/base_link.stl" scale="0.001 0.001 0.001"/>
      </geometry>
    </collision>
  </link>
  <link name="old_component__25__1">
    <inertial>
      <origin xyz="-0.0010554319034483655 -0.010177955025813722 0.0099605153071331" rpy="0 0 0"/>
      <mass value="0.2605710862815951"/>
      <inertia ixx="4.6e-05" iyy="7.1e-05" izz="4.2e-05" ixy="0.0" iyz="-0.0" ixz="1e-06"/>
    </inertial>
    <visual>
      <origin xyz="0.01125 0.056859 -0.300753" rpy="0 0 0"/>
      <geometry>
        <mesh filename="package://URDF_description/meshes/old_component__25__1.stl" scale="0.001 0.001 0.001"/>
      </geometry>
      <material name="silver"/>
    </visual>
    <collision>
      <origin xyz="0.01125 0.056859 -0.300753" rpy="0 0 0"/>
      <geometry>
        <mesh filename="package://URDF_description/meshes/old_component__25__1.stl" scale="0.001 0.001 0.001"/>
      </geometry>
    </collision>
  </link>
  <link name="old_component__23__1">
    <inertial>
      <origin xyz="-0.0013721079730043672 0.010183257082741967 0.009960041415219167" rpy="0 0 0"/>
      <mass value="0.26058347817133687"/>
      <inertia ixx="4.6e-05" iyy="7.1e-05" izz="4.2e-05" ixy="-0.0" iyz="0.0" ixz="1e-06"/>
    </inertial>
    <visual>
      <origin xyz="0.010932 -0.07264 -0.300746" rpy="0 0 0"/>
      <geometry>
        <mesh filename="package://URDF_description/meshes/old_component__23__1.stl" scale="0.001 0.001 0.001"/>
      </geometry>
      <material name="silver"/>
    </visual>
    <collision>
      <origin xyz="0.010932 -0.07264 -0.300746" rpy="0 0 0"/>
      <geometry>
        <mesh filename="package://URDF_description/meshes/old_component__23__1.stl" scale="0.001 0.001 0.001"/>
      </geometry>
    </collision>
  </link>
  <link name="old_component__20__1">
    <inertial>
      <origin xyz="-0.025108010465582926 0.020534482343403035 -0.07938553469074466" rpy="0 0 0"/>
      <mass value="0.4795683297989441"/>
      <inertia ixx="0.0005" iyy="0.000461" izz="0.000198" ixy="-3e-06" iyz="0.000142" ixz="6e-06"/>
    </inertial>
    <visual>
      <origin xyz="-0.015754 0.067037 -0.300753" rpy="0 0 0"/>
      <geometry>
        <mesh filename="package://URDF_description/meshes/old_component__20__1.stl" scale="0.001 0.001 0.001"/>
      </geometry>
      <material name="silver"/>
    </visual>
    <collision>
      <origin xyz="-0.015754 0.067037 -0.300753" rpy="0 0 0"/>
      <geometry>
        <mesh filename="package://URDF_description/meshes/old_component__20__1.stl" scale="0.001 0.001 0.001"/>
      </geometry>
    </collision>
  </link>
  <link name="old_component__19__1">
    <inertial>
      <origin xyz="-0.029491082579912755 0.0039567541577458926 -0.1016008471361324" rpy="0 0 0"/>
      <mass value="0.5723786894338777"/>
      <inertia ixx="0.001158" iyy="0.001268" izz="0.00017" ixy="1e-06" iyz="2e-06" ixz="-0.000323"/>
    </inertial>
    <visual>
      <origin xyz="0.009024 0.071577 -0.195159" rpy="0 0 0"/>
      <geometry>
        <mesh filename="package://URDF_description/meshes/old_component__19__1.stl" scale="0.001 0.001 0.001"/>
      </geometry>
      <material name="silver"/>
    </visual>
    <collision>
      <origin xyz="0.009024 0.071577 -0.195159" rpy="0 0 0"/>
      <geometry>
        <mesh filename="package://URDF_description/meshes/old_component__19__1.stl" scale="0.001 0.001 0.001"/>
      </geometry>
    </collision>
  </link>
  <link name="old_component__22__1">
    <inertial>
      <origin xyz="0.010148909868078046 0.0014454123231728566 0.009960061611517447" rpy="0 0 0"/>
      <mass value="0.260583085238151"/>
      <inertia ixx="7.1e-05" iyy="4.6e-05" izz="4.2e-05" ixy="0.0" iyz="-1e-06" ixz="0.0"/>
    </inertial>
    <visual>
      <origin xyz="0.018503 0.067568 -0.050454" rpy="0 0 0"/>
      <geometry>
        <mesh filename="package://URDF_description/meshes/old_component__22__1.stl" scale="0.001 0.001 0.001"/>
      </geometry>
      <material name="silver"/>
    </visual>
    <collision>
      <origin xyz="0.018503 0.067568 -0.050454" rpy="0 0 0"/>
      <geometry>
        <mesh filename="package://URDF_description/meshes/old_component__22__1.stl" scale="0.001 0.001 0.001"/>
      </geometry>
    </collision>
  </link>
  <link name="old_component__21__1">
    <inertial>
      <origin xyz="-0.0038360250370360807 0.0260878632088187 -0.050533848086451186" rpy="0 0 0"/>
      <mass value="0.42535185084301863"/>
      <inertia ixx="0.000201" iyy="0.000374" izz="0.000441" ixy="-0.0" iyz="-0.0" ixz="-5e-06"/>
    </inertial>
    <visual>
      <origin xyz="0.008354 0.094498 -0.050454" rpy="0 0 0"/>
      <geometry>
        <mesh filename="package://URDF_description/meshes/old_component__21__1.stl" scale="0.001 0.001 0.001"/>
      </geometry>
      <material name="silver"/>
    </visual>
    <collision>
      <origin xyz="0.008354 0.094498 -0.050454" rpy="0 0 0"/>
      <geometry>
        <mesh filename="package://URDF_description/meshes/old_component__21__1.stl" scale="0.001 0.001 0.001"/>
      </geometry>
    </collision>
  </link>
  <link name="old_component__17__1">
    <inertial>
      <origin xyz="-0.025086134509350884 -0.019584458432278365 -0.07938591030825276" rpy="0 0 0"/>
      <mass value="0.4795660415586759"/>
      <inertia ixx="0.0005" iyy="0.000461" izz="0.000198" ixy="3e-06" iyz="-0.000142" ixz="6e-06"/>
    </inertial>
    <visual>
      <origin xyz="-0.016072 -0.082823 -0.300746" rpy="0 0 0"/>
      <geometry>
        <mesh filename="package://URDF_description/meshes/old_component__17__1.stl" scale="0.001 0.001 0.001"/>
      </geometry>
      <material name="silver"/>
    </visual>
    <collision>
      <origin xyz="-0.016072 -0.082823 -0.300746" rpy="0 0 0"/>
      <geometry>
        <mesh filename="package://URDF_description/meshes/old_component__17__1.stl" scale="0.001 0.001 0.001"/>
      </geometry>
    </collision>
  </link>
  <link name="old_component__16__1">
    <inertial>
      <origin xyz="-0.029491076838213486 -0.003956632577475125 -0.10160079326267875" rpy="0 0 0"/>
      <mass value="0.5723780660401575"/>
      <inertia ixx="0.001158" iyy="0.001268" izz="0.00017" ixy="-1e-06" iyz="-2e-06" ixz="-0.000323"/>
    </inertial>
    <visual>
      <origin xyz="0.008684 -0.088313 -0.195152" rpy="0 0 0"/>
      <geometry>
        <mesh filename="package://URDF_description/meshes/old_component__16__1.stl" scale="0.001 0.001 0.001"/>
      </geometry>
      <material name="silver"/>
    </visual>
    <collision>
      <origin xyz="0.008684 -0.088313 -0.195152" rpy="0 0 0"/>
      <geometry>
        <mesh filename="package://URDF_description/meshes/old_component__16__1.stl" scale="0.001 0.001 0.001"/>
      </geometry>
    </collision>
  </link>
  <link name="old_component__14__1">
    <inertial>
      <origin xyz="0.010216801636088587 -0.0014452836669609503 0.009959962708194117" rpy="0 0 0"/>
      <mass value="0.26058568857338693"/>
      <inertia ixx="7.1e-05" iyy="4.6e-05" izz="4.2e-05" ixy="-0.0" iyz="1e-06" ixz="0.0"/>
    </inertial>
    <visual>
      <origin xyz="0.018163 -0.084304 -0.050447" rpy="0 0 0"/>
      <geometry>
        <mesh filename="package://URDF_description/meshes/old_component__14__1.stl" scale="0.001 0.001 0.001"/>
      </geometry>
      <material name="silver"/>
    </visual>
    <collision>
      <origin xyz="0.018163 -0.084304 -0.050447" rpy="0 0 0"/>
      <geometry>
        <mesh filename="package://URDF_description/meshes/old_component__14__1.stl" scale="0.001 0.001 0.001"/>
      </geometry>
    </collision>
  </link>
  <link name="old_component__18__1">
    <inertial>
      <origin xyz="-0.003836011886673152 -0.025999620351597932 -0.050533600876661144" rpy="0 0 0"/>
      <mass value="0.42535393165731183"/>
      <inertia ixx="0.000201" iyy="0.000374" izz="0.000441" ixy="0.0" iyz="0.0" ixz="-5e-06"/>
    </inertial>
    <visual>
      <origin xyz="0.007946 -0.111234 -0.050447" rpy="0 0 0"/>
      <geometry>
        <mesh filename="package://URDF_description/meshes/old_component__18__1.stl" scale="0.001 0.001 0.001"/>
      </geometry>
      <material name="silver"/>
    </visual>
    <collision>
      <origin xyz="0.007946 -0.111234 -0.050447" rpy="0 0 0"/>
      <geometry>
        <mesh filename="package://URDF_description/meshes/old_component__18__1.stl" scale="0.001 0.001 0.001"/>
      </geometry>
    </collision>
  </link>
  <link name="Component104_1">
    <inertial>
      <origin xyz="0.0004996878831269973 0.02734500634448242 0.00896780014474241" rpy="0 0 0"/>
      <mass value="0.260645951134301"/>
      <inertia ixx="7.1e-05" iyy="4.2e-05" izz="4.6e-05" ixy="0.0" iyz="1e-06" ixz="0.0"/>
    </inertial>
    <visual>
      <origin xyz="0.011804 -0.008368 -0.332395" rpy="0 0 0"/>
      <geometry>
        <mesh filename="package://URDF_description/meshes/Component104_1.stl" scale="0.001 0.001 0.001"/>
      </geometry>
      <material name="silver"/>
    </visual>
    <collision>
      <origin xyz="0.011804 -0.008368 -0.332395" rpy="0 0 0"/>
      <geometry>
        <mesh filename="package://URDF_description/meshes/Component104_1.stl" scale="0.001 0.001 0.001"/>
      </geometry>
    </collision>
  </link>
  <link name="Component103_1">
    <inertial>
      <origin xyz="0.0001816438125570169 -0.0273436447861984 0.008967326406254417" rpy="0 0 0"/>
      <mass value="0.260658112795213"/>
      <inertia ixx="7.1e-05" iyy="4.2e-05" izz="4.6e-05" ixy="-0.0" iyz="-1e-06" ixz="0.0"/>
    </inertial>
    <visual>
      <origin xyz="0.011804 -0.008368 -0.332395" rpy="0 0 0"/>
      <geometry>
        <mesh filename="package://URDF_description/meshes/Component103_1.stl" scale="0.001 0.001 0.001"/>
      </geometry>
      <material name="silver"/>
    </visual>
    <collision>
      <origin xyz="0.011804 -0.008368 -0.332395" rpy="0 0 0"/>
      <geometry>
        <mesh filename="package://URDF_description/meshes/Component103_1.stl" scale="0.001 0.001 0.001"/>
      </geometry>
    </collision>
  </link>
  <link name="old_component__24__1">
    <inertial>
      <origin xyz="-0.009584482225170093 0.002892011357412988 -0.010242130854528853" rpy="0 0 0"/>
      <mass value="0.2606766909017712"/>
      <inertia ixx="4.2e-05" iyy="4.6e-05" izz="7.1e-05" ixy="1e-06" iyz="-0.0" ixz="0.0"/>
    </inertial>
    <visual>
      <origin xyz="0.011622 0.028932 -0.310995" rpy="0 0 0"/>
      <geometry>
        <mesh filename="package://URDF_description/meshes/old_component__24__1.stl" scale="0.001 0.001 0.001"/>
      </geometry>
      <material name="silver"/>
    </visual>
    <collision>
      <origin xyz="0.011622 0.028932 -0.310995" rpy="0 0 0"/>
      <geometry>
        <mesh filename="package://URDF_description/meshes/old_component__24__1.stl" scale="0.001 0.001 0.001"/>
      </geometry>
    </collision>
  </link>
  <link name="old_component__15__1">
    <inertial>
      <origin xyz="-0.00958582114085108 -0.0028961550072031106 -0.010249054751743758" rpy="0 0 0"/>
      <mass value="0.2606418768017664"/>
      <inertia ixx="4.2e-05" iyy="4.6e-05" izz="7.1e-05" ixy="-1e-06" iyz="0.0" ixz="0.0"/>
    </inertial>
    <visual>
      <origin xyz="0.011304 -0.045668 -0.310995" rpy="0 0 0"/>
      <geometry>
        <mesh filename="package://URDF_description/meshes/old_component__15__1.stl" scale="0.001 0.001 0.001"/>
      </geometry>
      <material name="silver"/>
    </visual>
    <collision>
      <origin xyz="0.011304 -0.045668 -0.310995" rpy="0 0 0"/>
      <geometry>
        <mesh filename="package://URDF_description/meshes/old_component__15__1.stl" scale="0.001 0.001 0.001"/>
      </geometry>
    </collision>
  </link>
  <joint name="Revolute 46" type="continuous">
    <origin xyz="0.000372 -0.027927 -0.010242" rpy="0 0 0"/>
    <parent link="old_component__24__1"/>
    <child link="old_component__25__1"/>
    <axis xyz="-0.0 -1.0 -0.0"/>
  </joint>
  <joint name="Revolute 54" type="continuous">
    <origin xyz="0.000372 0.026972 -0.010249" rpy="0 0 0"/>
    <parent link="old_component__15__1"/>
    <child link="old_component__23__1"/>
    <axis xyz="-0.0 1.0 0.0"/>
  </joint>
  <joint name="Revolute 66" type="continuous">
    <origin xyz="0.027004 -0.010178 0.0" rpy="0 0 0"/>
    <parent link="old_component__25__1"/>
    <child link="old_component__20__1"/>
    <axis xyz="1.0 0.0 -0.0"/>
  </joint>
  <joint name="Revolute 67" type="continuous">
    <origin xyz="-0.024778 -0.00454 -0.105594" rpy="0 0 0"/>
    <parent link="old_component__20__1"/>
    <child link="old_component__19__1"/>
    <axis xyz="-0.0 -1.0 -0.0"/>
  </joint>
  <joint name="Revolute 68" type="continuous">
    <origin xyz="-0.009479 0.004009 -0.144705" rpy="0 0 0"/>
    <parent link="old_component__19__1"/>
    <child link="old_component__22__1"/>
    <axis xyz="1.0 0.0 0.0"/>
  </joint>
  <joint name="Revolute 69" type="continuous">
    <origin xyz="0.010149 -0.02693 0.0" rpy="0 0 0"/>
    <parent link="old_component__22__1"/>
    <child link="old_component__21__1"/>
    <axis xyz="0.0 -1.0 -0.0"/>
  </joint>
  <joint name="Revolute 70" type="continuous">
    <origin xyz="0.027004 0.010183 0.0" rpy="0 0 0"/>
    <parent link="old_component__23__1"/>
    <child link="old_component__17__1"/>
    <axis xyz="1.0 0.0 -0.0"/>
  </joint>
  <joint name="Revolute 71" type="continuous">
    <origin xyz="-0.024756 0.00549 -0.105594" rpy="0 0 0"/>
    <parent link="old_component__17__1"/>
    <child link="old_component__16__1"/>
    <axis xyz="-0.0 1.0 0.0"/>
  </joint>
  <joint name="Revolute 72" type="continuous">
    <origin xyz="-0.009479 -0.004009 -0.144705" rpy="0 0 0"/>
    <parent link="old_component__16__1"/>
    <child link="old_component__14__1"/>
    <axis xyz="1.0 0.0 -0.0"/>
  </joint>
  <joint name="Revolute 73" type="continuous">
    <origin xyz="0.010217 0.02693 0.0" rpy="0 0 0"/>
    <parent link="old_component__14__1"/>
    <child link="old_component__18__1"/>
    <axis xyz="-0.0 1.0 0.0"/>
  </joint>
  <joint name="Revolute 90" type="continuous">
    <origin xyz="-0.011804 0.008368 0.332395" rpy="0 0 0"/>
    <parent link="base_link"/>
    <child link="Component104_1"/>
    <axis xyz="0.0 -0.0 1.0"/>
  </joint>
  <joint name="Revolute 91" type="continuous">
    <origin xyz="-0.011804 0.008368 0.332395" rpy="0 0 0"/>
    <parent link="base_link"/>
    <child link="Component103_1"/>
    <axis xyz="0.0 -0.0 1.0"/>
  </joint>
  <joint name="Revolute 92" type="continuous">
    <origin xyz="0.000182 -0.0373 -0.0214" rpy="0 0 0"/>
    <parent link="Component103_1"/>
    <child link="old_component__24__1"/>
    <axis xyz="-0.0 0.0 -1.0"/>
  </joint>
  <joint name="Revolute 93" type="continuous">
    <origin xyz="0.0005 0.0373 -0.0214" rpy="0 0 0"/>
    <parent link="Component104_1"/>
    <child link="old_component__15__1"/>
    <axis xyz="-0.0 0.0 -1.0"/>
  </joint>
</robot>
